Workbook

Sheet Dashboard
A1: NHS Hospital Directory KPI Dashboard
A2: Source: NHS ODS hospital directory (1,211 hospitals, England), cleaned via ETL. All figures are live formulas over the Data sheet.
A4: KPI | B4: Target (edit) | C4: Actual | D4: Status
A5: Total hospitals | B5: n/a | C5: =COUNTA(Data!$A$2:$A$1212) -> 1211 | D5: =IF(ISNUMBER(B5),IF(C5>=B5,"Meets target","Below target"),"-") -> -
A6: NHS Sector hospitals | B6: n/a | C6: =COUNTIFS(Data!$D$2:$D$1212,"NHS Sector") -> 743 | D6: =IF(ISNUMBER(B6),IF(C6>=B6,"Meets target","Below target"),"-") -> -
A7: Independent Sector hospitals | B7: n/a | C7: =COUNTIFS(Data!$D$2:$D$1212,"Independent Sector") -> 468 | D7: =IF(ISNUMBER(B7),IF(C7>=B7,"Meets target","Below target"),"-") -> -
A8: Independent share of hospitals | B8: n/a | C8: =C7/C5 -> 0.38645747 | D8: =IF(ISNUMBER(B8),IF(C8>=B8,"Meets target","Below target"),"-") -> -
A9: Parent organisations | B9: n/a | C9: =ROUND(SUMPRODUCT(1/COUNTIF(Data!$F$2:$F$1212,Data!$F$2:$F$1212)),0) -> 307 | D9: =IF(ISNUMBER(B9),IF(C9>=B9,"Meets target","Below target"),"-") -> -
A10: Records with phone number | B10: 0.9 | C10: =COUNTIFS(Data!$N$2:$N$1212,"<>")/C5 -> 0.79355904 | D10: =IF(ISNUMBER(B10),IF(C10>=B10,"Meets target","Below target"),"-") -> Below target
A11: Records with email | B11: 0.5 | C11: =COUNTIFS(Data!$O$2:$O$1212,"<>")/C5 -> 0.34847234 | D11: =IF(ISNUMBER(B11),IF(C11>=B11,"Meets target","Below target"),"-") -> Below target
A12: Records with website | B12: 0.9 | C12: =COUNTIFS(Data!$P$2:$P$1212,"<>")/C5 -> 0.70437655 | D12: =IF(ISNUMBER(B12),IF(C12>=B12,"Meets target","Below target"),"-") -> Below target
A13: Records with postcode | B13: 0.99 | C13: =COUNTIFS(Data!$J$2:$J$1212,"<>")/C5 -> 0.99917424 | D13: =IF(ISNUMBER(B13),IF(C13>=B13,"Meets target","Below target"),"-") -> Meets target
A14: Records with coordinates | B14: 0.99 | C14: =COUNTIFS(Data!$K$2:$K$1212,"<>")/C5 -> 0.99834847 | D14: =IF(ISNUMBER(B14),IF(C14>=B14,"Meets target","Below target"),"-") -> Meets target
A15: Records with county identified | B15: 0.98 | C15: =1-COUNTIFS(Data!$H$2:$H$1212,"Unknown County")/C5 -> 0.98431049 | D15: =IF(ISNUMBER(B15),IF(C15>=B15,"Meets target","Below target"),"-") -> Meets target
A16: Targets are illustrative assumptions set by the analyst (blue cells, editable), not official NHS standards.
A18: Sector | B18: Hospitals | C18: Share
A19: Independent Sector | B19: =COUNTIFS(Data!$D$2:$D$1212,$A19) -> 468 | C19: =B19/SUM(B$19:B$20) -> 0.38645747
A20: NHS Sector | B20: =COUNTIFS(Data!$D$2:$D$1212,$A20) -> 743 | C20: =B20/SUM(B$19:B$20) -> 0.61354253

Sheet By Region
A1: Hospital Provision by Region
A2: Red = independent share above the national share. 'Unknown' = county could not be determined from the source data.
A4: Region | B4: Hospitals | C4: NHS Sector | D4: Independent Sector | E4: % Independent | F4: % of National Total
A5: South East | B5: =COUNTIFS(Data!$I$2:$I$1212,$A5) -> 230 | C5: =COUNTIFS(Data!$I$2:$I$1212,$A5,Data!$D$2:$D$1212,"NHS Sector") -> 112 | D5: =COUNTIFS(Data!$I$2:$I$1212,$A5,Data!$D$2:$D$1212,"Independent Sector") -> 118 | E5: =IFERROR(D5/B5,0) -> 0.51304348 | F5: =B5/B$15 -> 0.18992568
A6: South West | B6: =COUNTIFS(Data!$I$2:$I$1212,$A6) -> 174 | C6: =COUNTIFS(Data!$I$2:$I$1212,$A6,Data!$D$2:$D$1212,"NHS Sector") -> 123 | D6: =COUNTIFS(Data!$I$2:$I$1212,$A6,Data!$D$2:$D$1212,"Independent Sector") -> 51 | E6: =IFERROR(D6/B6,0) -> 0.29310345 | F6: =B6/B$15 -> 0.14368291
A7: North West | B7: =COUNTIFS(Data!$I$2:$I$1212,$A7) -> 138 | C7: =COUNTIFS(Data!$I$2:$I$1212,$A7,Data!$D$2:$D$1212,"NHS Sector") -> 86 | D7: =COUNTIFS(Data!$I$2:$I$1212,$A7,Data!$D$2:$D$1212,"Independent Sector") -> 52 | E7: =IFERROR(D7/B7,0) -> 0.37681159 | F7: =B7/B$15 -> 0.11395541
A8: East of England | B8: =COUNTIFS(Data!$I$2:$I$1212,$A8) -> 128 | C8: =COUNTIFS(Data!$I$2:$I$1212,$A8,Data!$D$2:$D$1212,"NHS Sector") -> 66 | D8: =COUNTIFS(Data!$I$2:$I$1212,$A8,Data!$D$2:$D$1212,"Independent Sector") -> 62 | E8: =IFERROR(D8/B8,0) -> 0.484375 | F8: =B8/B$15 -> 0.10569777
A9: London | B9: =COUNTIFS(Data!$I$2:$I$1212,$A9) -> 124 | C9: =COUNTIFS(Data!$I$2:$I$1212,$A9,Data!$D$2:$D$1212,"NHS Sector") -> 81 | D9: =COUNTIFS(Data!$I$2:$I$1212,$A9,Data!$D$2:$D$1212,"Independent Sector") -> 43 | E9: =IFERROR(D9/B9,0) -> 0.34677419 | F9: =B9/B$15 -> 0.10239472
A10: West Midlands | B10: =COUNTIFS(Data!$I$2:$I$1212,$A10) -> 123 | C10: =COUNTIFS(Data!$I$2:$I$1212,$A10,Data!$D$2:$D$1212,"NHS Sector") -> 75 | D10: =COUNTIFS(Data!$I$2:$I$1212,$A10,Data!$D$2:$D$1212,"Independent Sector") -> 48 | E10: =IFERROR(D10/B10,0) -> 0.3902439 | F10: =B10/B$15 -> 0.10156895
A11: Yorkshire and The Humber | B11: =COUNTIFS(Data!$I$2:$I$1212,$A11) -> 120 | C11: =COUNTIFS(Data!$I$2:$I$1212,$A11,Data!$D$2:$D$1212,"NHS Sector") -> 83 | D11: =COUNTIFS(Data!$I$2:$I$1212,$A11,Data!$D$2:$D$1212,"Independent Sector") -> 37 | E11: =IFERROR(D11/B11,0) -> 0.30833333 | F11: =B11/B$15 -> 0.09909166
A12: East Midlands | B12: =COUNTIFS(Data!$I$2:$I$1212,$A12) -> 86 | C12: =COUNTIFS(Data!$I$2:$I$1212,$A12,Data!$D$2:$D$1212,"NHS Sector") -> 53 | D12: =COUNTIFS(Data!$I$2:$I$1212,$A12,Data!$D$2:$D$1212,"Independent Sector") -> 33 | E12: =IFERROR(D12/B12,0) -> 0.38372093 | F12: =B12/B$15 -> 0.07101569
A13: North East | B13: =COUNTIFS(Data!$I$2:$I$1212,$A13) -> 69 | C13: =COUNTIFS(Data!$I$2:$I$1212,$A13,Data!$D$2:$D$1212,"NHS Sector") -> 50 | D13: =COUNTIFS(Data!$I$2:$I$1212,$A13,Data!$D$2:$D$1212,"Independent Sector") -> 19 | E13: =IFERROR(D13/B13,0) -> 0.27536232 | F13: =B13/B$15 -> 0.056977704
A14: Unknown | B14: =COUNTIFS(Data!$I$2:$I$1212,$A14) -> 19 | C14: =COUNTIFS(Data!$I$2:$I$1212,$A14,Data!$D$2:$D$1212,"NHS Sector") -> 14 | D14: =COUNTIFS(Data!$I$2:$I$1212,$A14,Data!$D$2:$D$1212,"Independent Sector") -> 5 | E14: =IFERROR(D14/B14,0) -> 0.26315789 | F14: =B14/B$15 -> 0.015689513
A15: England total | B15: =SUM(B5:B14) -> 1211 | C15: =SUM(C5:C14) -> 743 | D15: =SUM(D5:D14) -> 468 | E15: =D15/B15 -> 0.38645747 | F15: =SUM(F5:F14) -> 1

Sheet Top Counties
A1: Top 15 Counties by Hospitals
A3: County | B3: Region | C3: Hospitals | D3: % of National | E3: Cumulative %
A4: Greater London | B4: London | C4: =COUNTIFS(Data!$H$2:$H$1212,$A4) -> 100 | D4: =C4/COUNTA(Data!$A$2:$A$1212) -> 0.082576383 | E4: =SUM(D$4:D4) -> 0.082576383
A5: West Midlands | B5: West Midlands | C5: =COUNTIFS(Data!$H$2:$H$1212,$A5) -> 62 | D5: =C5/COUNTA(Data!$A$2:$A$1212) -> 0.051197358 | E5: =SUM(D$4:D5) -> 0.13377374
A6: Kent | B6: South East | C6: =COUNTIFS(Data!$H$2:$H$1212,$A6) -> 52 | D6: =C6/COUNTA(Data!$A$2:$A$1212) -> 0.042939719 | E6: =SUM(D$4:D6) -> 0.17671346
A7: Surrey | B7: South East | C7: =COUNTIFS(Data!$H$2:$H$1212,$A7) -> 46 | D7: =C7/COUNTA(Data!$A$2:$A$1212) -> 0.037985136 | E7: =SUM(D$4:D7) -> 0.2146986
A8: Lancashire | B8: North West | C8: =COUNTIFS(Data!$H$2:$H$1212,$A8) -> 44 | D8: =C8/COUNTA(Data!$A$2:$A$1212) -> 0.036333609 | E8: =SUM(D$4:D8) -> 0.2510322
A9: Devon | B9: South West | C9: =COUNTIFS(Data!$H$2:$H$1212,$A9) -> 43 | D9: =C9/COUNTA(Data!$A$2:$A$1212) -> 0.035507845 | E9: =SUM(D$4:D9) -> 0.28654005
A10: Essex | B10: East of England | C10: =COUNTIFS(Data!$H$2:$H$1212,$A10) -> 42 | D10: =C10/COUNTA(Data!$A$2:$A$1212) -> 0.034682081 | E10: =SUM(D$4:D10) -> 0.32122213
A11: West Yorkshire | B11: Yorkshire and The Humber | C11: =COUNTIFS(Data!$H$2:$H$1212,$A11) -> 42 | D11: =C11/COUNTA(Data!$A$2:$A$1212) -> 0.034682081 | E11: =SUM(D$4:D11) -> 0.35590421
A12: Hampshire | B12: South East | C12: =COUNTIFS(Data!$H$2:$H$1212,$A12) -> 38 | D12: =C12/COUNTA(Data!$A$2:$A$1212) -> 0.031379026 | E12: =SUM(D$4:D12) -> 0.38728324
A13: Merseyside | B13: North West | C13: =COUNTIFS(Data!$H$2:$H$1212,$A13) -> 34 | D13: =C13/COUNTA(Data!$A$2:$A$1212) -> 0.02807597 | E13: =SUM(D$4:D13) -> 0.41535921
A14: Dorset | B14: South West | C14: =COUNTIFS(Data!$H$2:$H$1212,$A14) -> 30 | D14: =C14/COUNTA(Data!$A$2:$A$1212) -> 0.024772915 | E14: =SUM(D$4:D14) -> 0.44013212
A15: North Yorkshire | B15: Yorkshire and The Humber | C15: =COUNTIFS(Data!$H$2:$H$1212,$A15) -> 29 | D15: =C15/COUNTA(Data!$A$2:$A$1212) -> 0.023947151 | E15: =SUM(D$4:D15) -> 0.46407927
... A18: Hertfordshire | B18: East of England | C18: =COUNTIFS(Data!$H$2:$H$1212,$A18) -> 27 | D18: =C18/COUNTA(Data!$A$2:$A$1212) -> 0.022295623 | E18: =SUM(D$4:D18) -> 0.53179191

Sheet Parent Organisations
A1: Top 15 Parent Organisations (Provider Concentration)
A3: Parent Organisation | B3: Hospitals | C3: % of National | D3: Sector (majority)
A4: BMI Healthcare | B4: =COUNTIFS(Data!$F$2:$F$1212,$A4) -> 43 | C4: =B4/COUNTA(Data!$A$2:$A$1212) -> 0.035507845 | D4: Independent Sector
A5: Spire Healthcare | B5: =COUNTIFS(Data!$F$2:$F$1212,$A5) -> 35 | C5: =B5/COUNTA(Data!$A$2:$A$1212) -> 0.028901734 | D5: Independent Sector
A6: Ramsay Healthcare UK Operations Limited | B6: =COUNTIFS(Data!$F$2:$F$1212,$A6) -> 31 | C6: =B6/COUNTA(Data!$A$2:$A$1212) -> 0.025598679 | D6: Independent Sector
A7: Nuffield Health | B7: =COUNTIFS(Data!$F$2:$F$1212,$A7) -> 29 | C7: =B7/COUNTA(Data!$A$2:$A$1212) -> 0.023947151 | D7: Independent Sector
A8: Cygnet Health Care Limited | B8: =COUNTIFS(Data!$F$2:$F$1212,$A8) -> 24 | C8: =B8/COUNTA(Data!$A$2:$A$1212) -> 0.019818332 | D8: NHS Sector
A9: Dorset Healthcare University NHS Foundation Trust | B9: =COUNTIFS(Data!$F$2:$F$1212,$A9) -> 20 | C9: =B9/COUNTA(Data!$A$2:$A$1212) -> 0.016515277 | D9: NHS Sector
A10: Birmingham and Solihull Mental Health NHS Foundation Trust | B10: =COUNTIFS(Data!$F$2:$F$1212,$A10) -> 18 | C10: =B10/COUNTA(Data!$A$2:$A$1212) -> 0.014863749 | D10: NHS Sector
A11: Priory Group Limited | B11: =COUNTIFS(Data!$F$2:$F$1212,$A11) -> 18 | C11: =B11/COUNTA(Data!$A$2:$A$1212) -> 0.014863749 | D11: Independent Sector
A12: Somerset Partnership NHS Foundation Trust | B12: =COUNTIFS(Data!$F$2:$F$1212,$A12) -> 15 | C12: =B12/COUNTA(Data!$A$2:$A$1212) -> 0.012386457 | D12: NHS Sector
A13: Royal Devon and Exeter NHS Foundation Trust | B13: =COUNTIFS(Data!$F$2:$F$1212,$A13) -> 14 | C13: =B13/COUNTA(Data!$A$2:$A$1212) -> 0.011560694 | D13: NHS Sector
A14: Southern Health NHS Foundation Trust | B14: =COUNTIFS(Data!$F$2:$F$1212,$A14) -> 14 | C14: =B14/COUNTA(Data!$A$2:$A$1212) -> 0.011560694 | D14: Independent Sector
A15: Norfolk and Suffolk NHS Foundation Trust | B15: =COUNTIFS(Data!$F$2:$F$1212,$A15) -> 13 | C15: =B15/COUNTA(Data!$A$2:$A$1212) -> 0.01073493 | D15: NHS Sector
... A18: Kent Community Health NHS Foundation Trust | B18: =COUNTIFS(Data!$F$2:$F$1212,$A18) -> 12 | C18: =B18/COUNTA(Data!$A$2:$A$1212) -> 0.009909166 | D18: NHS Sector
A20: Sector (majority) is the most common sector among that parent's hospitals, computed when the workbook was built (static text).

Sheet Data Completeness
A1: Data Completeness by Sector (% of hospitals with the field populated)
A3: Sector | B3: Hospitals | C3: Phone | D3: Email | E3: Website | F3: Postcode | G3: Coordinates
A4: Independent Sector | B4: =COUNTIFS(Data!$D$2:$D$1212,$A4) -> 468 | C4: =IFERROR(COUNTIFS(Data!$D$2:$D$1212,$A4,Data!$N$2:$N$1212,"<>")/$B4,0) -> 0.66880342 | D4: =IFERROR(COUNTIFS(Data!$D$2:$D$1212,$A4,Data!$O$2:$O$1212,"<>")/$B4,0) -> 0.39102564 | E4: =IFERROR(COUNTIFS(Data!$D$2:$D$1212,$A4,Data!$P$2:$P$1212,"<>")/$B4,0) -> 0.56837607 | F4: =IFERROR(COUNTIFS(Data!$D$2:$D$1212,$A4,Data!$J$2:$J$1212,"<>")/$B4,0) -> 1 | G4: =IFERROR(COUNTIFS(Data!$D$2:$D$1212,$A4,Data!$K$2:$K$1212,"<>")/$B4,0) -> 0.99786325
A5: NHS Sector | B5: =COUNTIFS(Data!$D$2:$D$1212,$A5) -> 743 | C5: =IFERROR(COUNTIFS(Data!$D$2:$D$1212,$A5,Data!$N$2:$N$1212,"<>")/$B5,0) -> 0.87213997 | D5: =IFERROR(COUNTIFS(Data!$D$2:$D$1212,$A5,Data!$O$2:$O$1212,"<>")/$B5,0) -> 0.32166891 | E5: =IFERROR(COUNTIFS(Data!$D$2:$D$1212,$A5,Data!$P$2:$P$1212,"<>")/$B5,0) -> 0.79004038 | F5: =IFERROR(COUNTIFS(Data!$D$2:$D$1212,$A5,Data!$J$2:$J$1212,"<>")/$B5,0) -> 0.9986541 | G5: =IFERROR(COUNTIFS(Data!$D$2:$D$1212,$A5,Data!$K$2:$K$1212,"<>")/$B5,0) -> 0.9986541

Sheet Data
A1: Hospital ID | B1: ODS Code | C1: Hospital Name | D1: Sector | E1: Subtype | F1: Parent Organisation | G1: City | H1: County | I1: Region | J1: Postcode | K1: Latitude | L1: Longitude | M1: PIMS Managed | N1: Phone | O1: Email | P1: Website | Q1: Possible Duplicate
A2: 17970 | B2: NDA07 | C2: Walton Community Hospital - Virgin Care Services Ltd | D2: Independent Sector | E2: Hospital | F2: Virgin Care Services Ltd | G2: Walton-on-Thames | H2: Surrey | I2: South East | J2: KT12 3LD | K2: 51.379997 | L2: -0.40604207 | M2: Yes | N2: 01932 414205 | Q2: No
A3: 17981 | B3: NDA18 | C3: Woking Community Hospital (Virgin Care) | D3: Independent Sector | E3: Hospital | F3: Virgin Care Services Ltd | G3: Woking | H3: Surrey | I3: South East | J3: GU22 7HS | K3: 51.315132 | L3: -0.55628949 | M3: Yes | N3: 01483 715911 | Q3: No
A4: 18102 | B4: NLT02 | C4: North Somerset Community Hospital | D4: NHS Sector | E4: Hospital | F4: North Somerset Community Partnership Community Interest Company | G4: Clevedon | H4: Avon | I4: South West | J4: BS21 6BS | K4: 51.437195 | L4: -2.8471928 | M4: Yes | N4: 01275 872212 | P4: http://www.nscphealth.co.uk | Q4: No
A5: 18138 | B5: NMP01 | C5: Bridgewater Hospital | D5: Independent Sector | E5: Hospital | F5: Bridgewater Hospital (Manchester) Ltd | G5: Manchester | H5: Greater Manchester | I5: North West | J5: M15 5AT | K5: 53.459743 | L5: -2.2454689 | M5: No | N5: 0161 2270000 | P5: https://www.bridgewaterhospital.com | Q5: No
A6: 18142 | B6: NMV01 | C6: Kneesworth House | D6: Independent Sector | E6: Hospital | F6: Partnerships In Care Ltd | G6: Royston | H6: Hertfordshire | I6: East of England | J6: SG8 5JP | K6: 52.078121 | L6: -0.030604055 | M6: Yes | N6: 01763 255 700 | O6: reception_kneesworthhouse@partnershipsincare.co.uk | P6: https://www.partnershipsincare.co.uk | Q6: No
A7: 18143 | B7: NMV02 | C7: Stockton Hall Hospital | D7: Independent Sector | E7: Hospital | F7: Partnerships In Care Ltd | G7: York | H7: North Yorkshire | I7: Yorkshire and The Humber | J7: YO32 9UN | K7: 53.995403 | L7: -1.0025526 | M7: Yes | N7: 01904 400 500 | O7: info@priorygroup.com | P7: https://www.priorygroup.com/stockton-hall | Q7: No
A8: 18271 | B8: NQ106 | C8: Fryatt Hospital, Harwich | D8: Independent Sector | E8: Hospital | F8: Anglian Community Enterprise Community Interest Company (ACE CIC) | G8: Harwich | H8: Essex | I8: East of England | J8: CO12 4EX | K8: 51.934696 | L8: 1.2614441 | M8: Yes | N8: 01255 201200 | Q8: No
A9: 18272 | B9: NQ108 | C9: Clacton Hospital | D9: Independent Sector | E9: Hospital | F9: Anglian Community Enterprise Community Interest Company (ACE CIC) | G9: Clacton | H9: Essex | I9: East of England | J9: CO15 1LH | K9: 51.786079 | L9: 1.1481875 | M9: Yes | N9: 01255 201717 | P9: https://www.esneft.nhs.uk/your-visit/our-wards/clacton-hospital | Q9: No
A10: 18289 | B10: NQ901 | C10: Lakeside Hospital | D10: Independent Sector | E10: Hospital | F10: Brookdale Healthcare Ltd (T/A Brookdale Care) | G10: Bedford | H10: Bedfordshire | I10: East of England | J10: MK44 3AS | K10: 52.198326 | L10: -0.31028071 | M10: No | Q10: No
A11: 18305 | B11: NQM01 | C11: Orthopaedics and Spine Specialist Hospital | D11: Independent Sector | E11: Hospital | F11: Orthopaedics and Spine Specialist Hospital | G11: Peterborough | H11: Cambridgeshire | I11: East of England | J11: PE3 8YA | K11: 52.604942 | L11: -0.28302181 | M11: Yes | N11: 01733 333156 | O11: info@orthospine.co.uk | Q11: No
A12: 18314 | B12: NR510 | C12: Lee Mill Hospital | D12: Independent Sector | E12: Hospital | F12: Livewell Southwest | G12: Plymouth | H12: Devon | I12: South West | J12: PL21 9HL | K12: 50.389484 | L12: -3.9596601 | M12: Yes | N12: 01752 314800 | Q12: No
A13: 18317 | B13: NR527 | C13: Mount Gould Hospital | D13: Independent Sector | E13: Hospital | F13: Livewell Southwest | G13: Plymouth | H13: Devon | I13: South West | J13: PL4 7QD | K13: 50.378403 | L13: -4.1127405 | M13: Yes | N13: 01752 268011 | P13: https://www.livewellsouthwest.co.uk | Q13: No
A14: 18351 | B14: NT202 | C14: Nuffield Health, Bournemouth Hospital | D14: Independent Sector | E14: Hospital | F14: Nuffield Health | G14: Bournemouth | H14: Dorset | I14: South West | J14: BH1 1RW | K14: 50.729755 | L14: -1.8697809 | M14: Yes | N14: 0800 015 5020 | O14: nuffieldhealth.ereferrals@nhs.net | P14: http://www.nuffieldhealth.com/individuals/centres/b/bournemouth | Q14: No
A15: 18352 | B15: NT204 | C15: Nuffield Health, Brentwood Hospital | D15: Independent Sector | E15: Hospital | F15: Nuffield Health | G15: Brentwood | H15: Essex | I15: East of England | J15: CM15 8EH | K15: 51.623333 | L15: 0.31283531 | M15: Yes | N15: 0800 015 5020 | O15: nuffieldhealth.ereferrals@nhs.net | P15: http://www.nuffieldhealth.com/brentwoodhospital | Q15: No
A16: 18353 | B16: NT205 | C16: Nuffield Health, Brighton Hospital | D16: Independent Sector | E16: Hospital | F16: Nuffield Health | G16: Brighton | H16: East Sussex | I16: South East | J16: BN2 6DX | K16: 50.834518 | L16: -0.081910513 | M16: Yes | N16: 0800 015 5020 | O16: nuffieldhealth.ereferrals@nhs.net | P16: http://www.nuffieldhealth.com/brightonhospital | Q16: No
A17: 18354 | B17: NT206 | C17: Nuffield Health, Bristol Hospital (Chesterfield) | D17: Independent Sector | E17: Hospital | F17: Nuffield Health | G17: Bristol | H17: Avon | I17: South West | J17: BS8 1BN | K17: 51.453609 | L17: -2.6159844 | M17: Yes | N17: 0800 015 5020 | O17: nuffieldhealth.ereferrals@nhs.net | P17: http://www.nuffieldhealth.com/hospitals/bristol | Q17: No
A18: 18356 | B18: NT209 | C18: Nuffield Health, Cambridge Hospital | D18: Independent Sector | E18: Hospital | F18: Nuffield Health | G18: Cambridge | H18: Cambridgeshire | I18: East of England | J18: CB2 8AF | K18: 52.190353 | L18: 0.1235586 | M18: Yes | N18: 0800 015 5020 | O18: nuffieldhealth.ereferrals@nhs.net | P18: http://www.nuffieldhealth.com/cambridgehospital | Q18: No
A19: 18357 | B19: NT210 | C19: Nuffield Health, The Grosvenor Hospital, Chester | D19: Independent Sector | E19: Hospital | F19: Nuffield Health | G19: Chester | H19: Cheshire | I19: North West | J19: CH4 7QP | K19: 53.176346 | L19: -2.8952467 | M19: Yes | N19: 0800 015 5020 | O19: nuffieldhealth.ereferrals@nhs.net | P19: http://www.nuffieldhealth.com/thegrosvenorhospitalchester | Q19: No
A20: 18358 | B20: NT211 | C20: Nuffield Health, Cheltenham Hospital | D20: Independent Sector | E20: Hospital | F20: Nuffield Health | G20: Cheltenham | H20: Gloucestershire | I20: South West | J20: GL51 6SY | K20: 51.89193 | L20: -2.1299055 | M20: Yes | N20: 0800 015 5020 | O20: nuffieldhealth.ereferrals@nhs.net | P20: http://www.nuffieldhealth.com/cheltenhamhospital | Q20: No
A21: 18359 | B21: NT212 | C21: Nuffield Health, Chichester Hospital | D21: Independent Sector | E21: Hospital | F21: Nuffield Health | G21: Chichester | H21: West Sussex | I21: South East | J21: PO19 6WB | K21: 50.84798 | L21: -0.78001314 | M21: Yes | N21: 0800 015 5020 | O21: nuffieldhealth.ereferrals@nhs.net | P21: http://www.nuffieldhealth.com/chichesterhospital | Q21: No
A22: 18360 | B22: NT213 | C22: Nuffield Health, Derby Hospital | D22: Independent Sector | E22: Hospital | F22: Nuffield Health | G22: Derby | H22: Derbyshire | I22: East Midlands | J22: DE23 4SN | K22: 52.893551 | L22: -1.5301552 | M22: Yes | N22: 0800 015 5020 | O22: nuffieldhealth.ereferrals@nhs.net | P22: http://www.nuffieldhealth.com/derbyhospital | Q22: No
A23: 18361 | B23: NT214 | C23: Nuffield Health, Wessex Hospital | D23: Independent Sector | E23: Hospital | F23: Nuffield Health | G23: Eastleigh | H23: Hampshire | I23: South East | J23: SO53 2DW | K23: 50.996975 | L23: -1.3593509 | M23: Yes | N23: 0800 015 5020 | O23: nuffieldhealth.ereferrals@nhs.net | P23: http://www.nuffieldhealth.com/hospitals/wessex | Q23: No
A24: 18362 | B24: NT215 | C24: Nuffield Health, Exeter Hospital | D24: Independent Sector | E24: Hospital | F24: Nuffield Health | G24: Exeter | H24: Devon | I24: South West | J24: EX2 4UG | K24: 50.716316 | L24: -3.5112717 | M24: Yes | N24: 0800 015 5020 | O24: nuffieldhealth.ereferrals@nhs.net | P24: http://www.nuffieldhealth.com/exeterhospital | Q24: No
A25: 18363 | B25: NT216 | C25: Nuffield Health, Guildford Hospital | D25: Independent Sector | E25: Hospital | F25: Nuffield Health | G25: Guildford | H25: Surrey | I25: South East | J25: GU2 7RF | K25: 51.241653 | L25: -0.61254358 | M25: Yes | N25: 01483 555800 | P25: http://www.nuffieldhealth.com/guildfordhospital | Q25: No
A26: 18365 | B26: NT218 | C26: Nuffield Health, Haywards Heath Hospital | D26: Independent Sector | E26: Hospital | F26: Nuffield Health | G26: Haywards Heath | H26: West Sussex | I26: South East | J26: RH16 1UD | K26: 51.008404 | L26: -0.10612142 | M26: Yes | N26: 0800 015 5020 | O26: nuffieldhealth.ereferrals@nhs.net | P26: http://www.nuffieldhealth.com/haywards-heathhospital | Q26: No
A27: 18366 | B27: NT219 | C27: Nuffield Health, Hereford Hospital | D27: Independent Sector | E27: Hospital | F27: Nuffield Health | G27: Hereford | H27: Herefordshire | I27: West Midlands | J27: HR1 1DF | K27: 52.063938 | L27: -2.6999545 | M27: Yes | N27: 01432 355131 | O27: nuffieldhealth.ereferrals@nhs.net | P27: http://www.nuffieldhealth.com/herefordhospital | Q27: No
A28: 18367 | B28: NT222 | C28: Nuffield Health, Ipswich Hospital | D28: Independent Sector | E28: Hospital | F28: Nuffield Health | G28: Ipswich | H28: Suffolk | I28: East of England | J28: IP4 5SW | K28: 52.04752 | L28: 1.2289459 | M28: Yes | N28: 0800 015 5020 | O28: nuffieldhealth.ereferrals@nhs.net | P28: http://www.nuffieldhealth.com/ipswichhospital | Q28: No
A29: 18368 | B29: NT224 | C29: Nuffield Health, Warwickshire Hospital | D29: Independent Sector | E29: Hospital | F29: Nuffield Health | G29: Leamington Spa | H29: Warwickshire | I29: West Midlands | J29: CV32 6RW | K29: 52.308498 | L29: -1.5438651 | M29: Yes | N29: 0800 015 5020 | O29: nuffieldhealth.ereferrals@nhs.net | P29: http://www.nuffieldhealth.com/warwickshirehospital | Q29: No
A30: 18369 | B30: NT225 | C30: Nuffield Health, Leeds Hospital | D30: Independent Sector | E30: Hospital | F30: Nuffield Health | G30: Leeds | H30: West Yorkshire | I30: Yorkshire and The Humber | J30: LS1 3EB | K30: 53.800659 | L30: -1.5542574 | M30: Yes | N30: 0113 388 2000 | O30: leedsnuffield@nhs.net | P30: https://www.nuffieldhealth.com/hospitals/leeds | Q30: No
A31: 18370 | B31: NT226 | C31: Nuffield Health, Leicester Hospital | D31: Independent Sector | E31: Hospital | F31: Nuffield Health | G31: Leicester | H31: Leicestershire | I31: East Midlands | J31: LE5 1HY | K31: 52.644257 | L31: -1.0712955 | M31: Yes | N31: 0800 015 5020 | O31: nuffieldhealth.ereferrals@nhs.net | P31: http://www.nuffieldhealth.com/leicesterhospital | Q31: No
A32: 18371 | B32: NT229 | C32: Nuffield Health, Newcastle-upon-Tyne Hospital | D32: Independent Sector | E32: Hospital | F32: Nuffield Health | G32: Newcastle Upon Tyne | H32: Tyne and Wear | I32: North East | J32: NE2 1JP | K32: 54.986614 | L32: -1.6052771 | M32: Yes | N32: 0800 015 5020 | O32: nuffieldhealth.ereferrals@nhs.net | P32: http://www.nuffieldhealth.com/newcastle-upon-tynehospital | Q32: No
A33: 18372 | B33: NT230 | C33: Nuffield Health, North Staffordshire Hospital | D33: Independent Sector | E33: Hospital | F33: Nuffield Health | G33: Newcastle Under Lyme | H33: Staffordshire | I33: West Midlands | J33: ST5 4DB | K33: 52.987408 | L33: -2.2230277 | M33: Yes | N33: 01782 382551 | O33: customerservice.enq@nuffieldhealth.com | P33: http://www.nuffieldhealth.com/northstaffordshirehospital | Q33: No
A34: 18373 | B34: NT233 | C34: Nuffield Health, Plymouth Hospital | D34: Independent Sector | E34: Hospital | F34: Nuffield Health | G34: Plymouth | H34: Devon | I34: South West | J34: PL6 8BG | K34: 50.418674 | L34: -4.1144481 | M34: Yes | N34: 0800 015 5020 | O34: nuffieldhealth.ereferrals@nhs.net | P34: http://www.nuffieldhealth.com/plymouthhospital | Q34: No
A35: 18374 | B35: NT235 | C35: Nuffield Health, Shrewsbury Hospital | D35: Independent Sector | E35: Hospital | F35: Nuffield Health | G35: Shrewsbury | H35: Shropshire | I35: West Midlands | J35: SY3 9DP | K35: 52.692257 | L35: -2.7714405 | M35: Yes | N35: 0800 015 5020 | O35: nuffieldhealth.ereferrals@nhs.net | P35: http://www.nuffieldhealth.com/shrewsburyhospital | Q35: No
A36: 18375 | B36: NT237 | C36: Nuffield Health, Tees Hospital | D36: Independent Sector | E36: Hospital | F36: Nuffield Health | G36: Stockton-on-Tees | H36: Cleveland | I36: North East | J36: TS20 1PX | K36: 54.593426 | L36: -1.3352185 | M36: Yes | N36: 0800 015 5020 | O36: tees.enquiries2@nuffieldhealth.com | P36: http://www.nuffieldhealth.com/teeshospital | Q36: No
A37: 18376 | B37: NT238 | C37: Nuffield Health, Taunton Hospital | D37: Independent Sector | E37: Hospital | F37: Nuffield Health | G37: Taunton | H37: Somerset | I37: South West | J37: TA2 6AN | K37: 51.029846 | L37: -3.1268978 | M37: Yes | N37: 0800 015 5020 | O37: nuffieldhealth.ereferrals@nhs.net | P37: http://www.nuffieldhealth.com/tauntonhospital | Q37: No
... A82: 18430 | B82: NT408 | C82: BMI The Chaucer Hospital | D82: Independent Sector | E82: Hospital | F82: BMI Healthcare | G82: Canterbury | H82: Kent | I82: South East | J82: CT4 7AR | K82: 51.261719 | L82: 1.0874593 | M82: Yes | N82: 01227 825100 | O82: chaucer@bmihealthcare.co.uk | P82: https://www.bmihealthcare.co.uk/hospitals/bmi-the-chaucer-hospital | Q82: No
A83: 18431 | B83: NT409 | C83: BMI Chelsfield Park Hospital | D83: Independent Sector | E83: Hospital | F83: BMI Healthcare | G83: Orpington | H83: Kent | I83: South East | J83: BR6 7RG | K83: 51.358467 | L83: 0.13086095 | M83: Yes | N83: 01689 877855 | P83: https://www.bmihealthcare.co.uk/hospitals/bmi-chelsfield-park-hospital | Q83: No
A84: 18432 | B84: NT410 | C84: BMI The Chiltern Hospital | D84: Independent Sector | E84: Hospital | F84: BMI Healthcare | G84: Great Missenden | H84: Buckinghamshire | I84: South East | J84: HP16 0EN | K84: 51.690533 | L84: -0.69365418 | M84: Yes | N84: 01494 890890 | O84: chiltern@bmihealthcare.co.uk | P84: https://www.bmihealthcare.co.uk/hospitals/bmi-the-chiltern-hospital | Q84: No
...

Sheet Cleaning Log
A1: ETL Cleaning Log
A3: Step | B3: Rows affected | C3: Detail
A4: Extract: raw rows loaded | B4: 1211 | C4: unnamed leading index column dropped; header 'Fax,,,' repaired to 'Fax'
A5: Trimmed / collapsed whitespace in text fields | B5: 24
A6: Blank strings converted to NULL | B6: 3533 | C6: all columns combined
A7: Coordinates outside UK bounding box set to NULL | B7: 0
A8: Missing coordinates left NULL | B8: 2
A9: Invalid postcodes set to NULL | B9: 0
A10: Missing postcode | B10: 1
A11: Cleaned trailing ',,,' artefacts in Phone | B11: 0
A12: Cleaned trailing ',,,' artefacts in Fax | B12: 1209
A13: Websites standardised (scheme added, host lower-cased, trailing '/' removed) | B13: 251
A14: SubType 'UNKNOWN' relabelled 'Not Specified' | B14: 244
A15: County labels standardised (Durham, Yorkshire(East Riding)) | B15: 12
A16: Missing county before imputation | B16: 238
A17: County imputed from same city's most common county | B17: 181
A18: County imputed from nearest hospital with known county (<=10 km) | B18: 38
... A20: Missing city -> 'Unknown City' | B20: 15
A21: Exact duplicate rows | B21: 0 | C21: none found
A22: Duplicate ODS codes / IDs | B22: 0 | C22: none found
A23: Possible duplicate sites flagged (same name + postcode, different ODS code); kept, not deleted | B23: 4
A24: Hospitals with at least one contact detail (rows in hospital_contacts) | B24: 961
A25: Load-ready hospitals rows | B25: 1211

Sheet Data Dictionary
A1: Table | B1: Column | C1: Data Type | D1: Key | E1: Nullable | F1: Description | G1: Rules / Notes
A2: regions | B2: region_id | C2: INT | D2: PK | E2: No | F2: Surrogate key | G2: Auto-increment
A3: regions | B3: region_name | C3: VARCHAR(40) | E3: No | F3: NHS England region (plus 'Unknown') | G3: UNIQUE; derived from county by lookup
A4: counties | B4: county_id | C4: INT | D4: PK | E4: No | F4: Surrogate key | G4: Auto-increment
A5: counties | B5: county_name | C5: VARCHAR(40) | E5: No | F5: County as recorded in ODS, standardised | G5: UNIQUE; 'Unknown County' where it could not be imputed
A6: counties | B6: region_id | C6: INT | D6: FK | E6: No | F6: -> regions.region_id | G6: Referential integrity
A7: cities | B7: city_id | C7: INT | D7: PK | E7: No | F7: Surrogate key | G7: Auto-increment
A8: cities | B8: city_name | C8: VARCHAR(60) | E8: No | F8: City / town | G8: 'Unknown City' where missing in source
A9: cities | B9: county_id | C9: INT | D9: FK | E9: No | F9: -> counties.county_id | G9: UNIQUE with city_name (same name can exist in two counties)
A10: sectors | B10: sector_id | C10: INT | D10: PK | E10: No | F10: Surrogate key | G10: Auto-increment
A11: sectors | B11: sector_name | C11: VARCHAR(30) | E11: No | F11: NHS Sector / Independent Sector | G11: UNIQUE
A12: hospital_subtypes | B12: subtype_id | C12: INT | D12: PK | E12: No | F12: Surrogate key | G12: Auto-increment
A13: hospital_subtypes | B13: subtype_name | C13: VARCHAR(40) | E13: No | F13: Hospital / Mental Health Hospital / Not Specified | G13: UNIQUE; source 'UNKNOWN' relabelled
A14: parent_organisations | B14: parent_id | C14: INT | D14: PK | E14: No | F14: Surrogate key | G14: Auto-increment
A15: parent_organisations | B15: parent_ods_code | C15: VARCHAR(10) | E15: No | F15: ODS code of the parent organisation | G15: UNIQUE
A16: parent_organisations | B16: parent_name | C16: VARCHAR(150) | E16: No | F16: Trust / company that operates the hospital
A17: hospitals | B17: hospital_id | C17: INT | D17: PK | E17: No | F17: OrganisationID from the source file | G17: Not auto-generated
A18: hospitals | B18: organisation_code | C18: VARCHAR(10) | E18: No | F18: ODS organisation code | G18: UNIQUE
A19: hospitals | B19: hospital_name | C19: VARCHAR(150) | E19: No | F19: Hospital / site name | G19: Trimmed; names are not unique (22 repeated)
A20: hospitals | B20: sector_id | C20: INT | D20: FK | E20: No | F20: -> sectors.sector_id | G20: Referential integrity
A21: hospitals | B21: subtype_id | C21: INT | D21: FK | E21: No | F21: -> hospital_subtypes.subtype_id | G21: Referential integrity
A22: hospitals | B22: parent_id | C22: INT | D22: FK | E22: No | F22: -> parent_organisations.parent_id | G22: Referential integrity
A23: hospitals | B23: city_id | C23: INT | D23: FK | E23: No | F23: -> cities.city_id (city -> county -> region) | G23: Referential integrity
A24: hospitals | B24: address_line_1 | C24: VARCHAR(100) | E24: Yes | F24: Address line 1 | G24: NULL if missing (27% missing in source)
A25: hospitals | B25: address_line_2 | C25: VARCHAR(100) | E25: Yes | F25: Address line 2 | G25: NULL if missing
A26: hospitals | B26: address_line_3 | C26: VARCHAR(100) | E26: Yes | F26: Address line 3 | G26: NULL if missing
A27: hospitals | B27: postcode | C27: VARCHAR(8) | E27: Yes | F27: UK postcode, upper-case, single space | G27: Format validated by regex; 1 missing
A28: hospitals | B28: latitude | C28: DECIMAL(9,6) | E28: Yes | F28: WGS84 latitude | G28: CHECK 49-61; 2 missing
A29: hospitals | B29: longitude | C29: DECIMAL(9,6) | E29: Yes | F29: WGS84 longitude | G29: CHECK -9 to 2; 2 missing
A30: hospitals | B30: is_pims_managed | C30: TINYINT(1) | E30: No | F30: 1 if record is managed in PIMS | G30: CHECK in (0,1)
A31: hospitals | B31: possible_duplicate | C31: TINYINT(1) | E31: No | F31: 1 if another record has the same name and postcode | G31: Flag only; row kept
A32: hospital_contacts | B32: hospital_id | C32: INT | D32: PK/FK | E32: No | F32: -> hospitals.hospital_id (1:0..1) | G32: Row exists only if the hospital has any contact detail
A33: hospital_contacts | B33: phone | C33: VARCHAR(30) | E33: Yes | F33: Switchboard phone | G33: Whitespace normalised
A34: hospital_contacts | B34: email | C34: VARCHAR(150) | E34: Yes | F34: Contact email | G34: Lower-cased
A35: hospital_contacts | B35: website | C35: VARCHAR(255) | E35: Yes | F35: Website URL | G35: https:// added if missing; host lower-cased; trailing / removed
A36: hospital_contacts | B36: fax | C36: VARCHAR(30) | E36: Yes | F36: Fax number | G36: Source column held ',,,' artefacts; cleaned
